<?xml version="1.0" encoding="utf-8"?>
<robot name="dyna1">
  <material name="yellow">
    <color rgba="0.1 0.45 1 1"/>
  </material>
  <material name="black">
    <color rgba="0.1 0.1 0.1 1"/>
  </material>
  <material name="grey">
    <color rgba="0.6 0.6 0.6 1"/>
  </material>
  <material name="white">
    <color rgba="1 1 1 1"/>
  </material>
	<material name="orange">
		<color rgba="1 0.35 0.05 1"/>
	</material>

  <link name="world"/>

  <link name="base_link">
    <visual>
      <geometry>
        <mesh filename="package://stl/Body.stl" scale="0.001 0.001 0.001"/>
      </geometry>
      <material name="grey"/>
      <origin rpy="0 0 0" xyz="0 0 0"/>  
    </visual>
    <collision>
      <geometry>
        <box size="0.499 0.247 0.186"/>
      </geometry>
      <origin rpy="0 0 0" xyz="-0.016533 0 0.029372"/>
    </collision>
    <inertial>
      <mass value="3.671"/>
			<origin rpy="0 0 0" xyz="0.00545 0.00008 0.008719"/>
      <inertia ixx="0.01643" ixy="-0.0002367" ixz="0.0025" iyy="0.0535" iyz="-0.0000116384" izz="0.05892"/>
    </inertial>
  </link>

	<joint name="world" type="fixed">
    <parent link="world"/>
    <child link="base_link"/>
  </joint>

  <link name="front_left_shoulder_link">
    <visual>
      <geometry>
        <mesh filename="package://stl/shoulder.stl" scale="0.001 0.001 0.001"/>
      </geometry>
      <origin rpy="0 0 0" xyz="0 0 0"/> 
      <material name="orange"/>
    </visual>
    <collision>
      <geometry>
        <box size="0.059 0.211013 0.118076"/>
      </geometry>
      <origin rpy="0 0 0" xyz="0 -0.080206 0.042257"/>
    </collision>
    <inertial>
      <mass value="0.505084"/>
			<origin rpy="0 0 0" xyz="-0.000225 -0.096893 0.058205"/>
      <inertia ixx="0.001676" ixy="-0.0000000635" ixz="0.0000000616" iyy="0.0004545" iyz="0.0002367" izz="0.001416"/>
    </inertial>
  </link>


  <link name="front_left_arm_link">
    <visual>
      <geometry>
        <mesh filename="package://stl/arm1.stl" scale="0.001 0.001 0.001"/>
      </geometry>
      <origin rpy="0 0 0" xyz="0 0 0"/> 
      <material name="white"/>
    </visual>
    <collision>
      <geometry>
        <box size="0.059 0.228758 0.08244"/>
      </geometry>
      <origin rpy="0 0 0" xyz="0.052 0.0944 0.016025"/>
    </collision>
    <inertial>
      <mass value="0.500063"/>
			<origin rpy="0 0 0" xyz="0.049769 0.079064 0.017355"/>
      <inertia ixx="0.001582" ixy="-0.0000885652" ixz="-0.0000123498" iyy="0.0003877" iyz="0.0001209" izz="0.001477"/>
    </inertial>
  </link>

  <link name="front_left_hand_link">
    <visual>
      <geometry>
        <mesh filename="package://stl/foot1.stl" scale="0.001 0.001 0.001"/>
      </geometry>
      <origin rpy="0 0 0" xyz="0 0 0"/> 
      <material name="yellow"/>
    </visual>
    <collision>
      <geometry>
        <cylinder length="0.138" radius="0.0101"/>
      </geometry>
      <origin rpy="0 1.570796 0" xyz="0.100811 -0.036862 0"/>
    </collision>
    <collision>
      <geometry>
        <cylinder length="0.0202" radius="0.015"/>
      </geometry>
      <origin rpy="0 0 1.570796" xyz="0.171811 -0.036862 0"/>
    </collision>
    <inertial>
      <mass value="0.066814"/>
			<origin rpy="0 0 0" xyz="0.07927 -0.025916 -0.001911"/>
      <inertia ixx="0.0000248634" ixy="0.0000574071" ixz="-0.000010119" iyy="0.0003695" iyz="0.0000032927" izz="0.0003872"/>
    </inertial>
  </link>

  <joint name="base_to_front_left_shoulder" type="revolute">
    <parent link="base_link"/>
    <child link="front_left_shoulder_link"/>
    <axis xyz="0 -1 0"/>
    <origin rpy="-1.57079632679 -1.57079632679 0" xyz="0.2352235 0.0985 0"/>
    <limit effort="100.0" lower="-0.6051" upper="0.6051" velocity="100"/>
    <dynamics damping="0.0" friction="0"/>
  </joint>

  <joint name="front_left_shoulder_to_arm" type="revolute">
    <parent link="front_left_shoulder_link"/>
    <child link="front_left_arm_link"/>
    <axis xyz="0 0 -1"/>
    <origin rpy="0 0 1.84649081579" xyz="0 0 0.0435"/>
    <limit effort="100.0" lower="-1.3135" upper="2.4337" velocity="100"/>
    <dynamics damping="0.0" friction="0"/>
  </joint>

  <joint name="front_left_arm_to_hand" type="revolute">
    <parent link="front_left_arm_link"/>
    <child link="front_left_hand_link"/>
    <axis xyz="0 0 1"/>
    <origin rpy="3.14159265359 0 1.103929191" xyz="0.0519 0.183458 0"/>
    <limit effort="100.0" lower="-0.8515" upper="2.6321" velocity="100"/>
    <dynamics damping="0.0" friction="0"/>
  </joint>

 




  <link name="front_right_shoulder_link">
    <visual>
      <geometry>
        <mesh filename="package://stl/shoulder.stl" scale="0.001 0.001 0.001"/>
      </geometry>
      <origin rpy="0 0 0" xyz="0 0 0"/> 
      <material name="orange"/>
    </visual>
    <collision>
      <geometry>
        <box size="0.059 0.211013 0.118076"/>
      </geometry>
      <origin rpy="0 0 0" xyz="0 -0.080206 0.042257"/>
    </collision>
    <inertial>
      <mass value="0.505084"/>
			<origin rpy="0 0 0" xyz="-0.000225 -0.096893 0.058205"/>
      <inertia ixx="0.001676" ixy="-0.0000000635" ixz="0.0000000616" iyy="0.0004545" iyz="0.0002367" izz="0.001416"/>
    </inertial>
  </link>

  <link name="front_right_arm_link">
    <visual>
      <geometry>
        <mesh filename="package://stl/arm2.stl" scale="0.001 0.001 0.001"/>
      </geometry>
      <origin rpy="0 0 0" xyz="0 0 0"/> 
      <material name="white"/>
    </visual>
    <collision>
      <geometry>
        <box size="0.059 0.228758 0.08244"/>
      </geometry>
      <origin rpy="0 0 0" xyz="-0.052 0.0944 0.016025"/>
    </collision>
    <inertial>
      <mass value="0.500063"/>
			<origin rpy="0 0 0" xyz="-0.049769 0.079064 0.017355"/>
      <inertia ixx="0.001582" ixy="0.000088512" ixz="0.0000124983" iyy="0.0003877" iyz="0.0001209" izz="0.001477"/>
    </inertial>
  </link>

  <link name="front_right_hand_link">
    <visual>
      <geometry>
        <mesh filename="package://stl/foot2.stl" scale="0.001 0.001 0.001"/>
      </geometry>
      <origin rpy="0 0 0" xyz="0 0 0"/> 
      <material name="yellow"/>
    </visual>
    <collision>
      <geometry>
        <cylinder length="0.138" radius="0.0101"/>
      </geometry>
      <origin rpy="0 1.570796 0" xyz="0.100811 -0.036862 0"/>
    </collision>
    <collision>
      <geometry>
        <cylinder length="0.0202" radius="0.015"/>
      </geometry>
      <origin rpy="0 0 1.570796" xyz="0.171811 -0.036862 0"/>
    </collision>
    <inertial>
      <mass value="0.066814"/>
			<origin rpy="0 0 0" xyz="0.07927 -0.025916 0.001911"/>
      <inertia ixx="0.0000248576" ixy="0.0000574076" ixz="0.0000101035" iyy="0.0003695" iyz="-0.0000032878" izz="0.0003872"/>
    </inertial>
  </link>

  <joint name="base_to_front_right_shoulder" type="revolute">
    <parent link="base_link"/>
    <child link="front_right_shoulder_link"/>
    <axis xyz="0 -1 0"/>
    <origin rpy="0 1.57079632679 -1.57079632679" xyz="0.2352235 -0.0985 0"/>
    <limit effort="100.0" lower="-0.6051" upper="0.6051" velocity="100"/>
    <dynamics damping="0.0" friction="0"/>
  </joint>

  <joint name="front_right_shoulder_to_arm" type="revolute">
    <parent link="front_right_shoulder_link"/>
    <child link="front_right_arm_link"/>
    <axis xyz="0 0 1"/>
    <origin rpy="0 0 -1.84649081579" xyz="0 0 0.0435"/>
    <limit effort="100.0" lower="-1.3135" upper="2.4337" velocity="100"/>
    <dynamics damping="0.0" friction="0"/>
  </joint>

  <joint name="front_right_arm_to_hand" type="revolute">
    <parent link="front_right_arm_link"/>
    <child link="front_right_hand_link"/>
    <axis xyz="0 0 1"/>
    <origin rpy="0 0 2.03766346259" xyz="-0.0519 0.183458 0"/>
    <limit effort="100.0" lower="-0.8515" upper="2.6321" velocity="100"/>
    <dynamics damping="0.0" friction="0"/>
  </joint>





  <link name="back_left_shoulder_link">
    <visual>
      <geometry>
        <mesh filename="package://stl/shoulder.stl" scale="0.001 0.001 0.001"/>
      </geometry>
      <origin rpy="0 0 0" xyz="0 0 0"/> 
      <material name="orange"/>
    </visual>
    <collision>
      <geometry>
        <box size="0.059 0.211013 0.118076"/>
      </geometry>
      <origin rpy="0 0 0" xyz="0 -0.080206 0.042257"/>
    </collision>
    <inertial>
      <mass value="0.505084"/>
			<origin rpy="0 0 0" xyz="-0.000225 -0.096893 0.058205"/>
      <inertia ixx="0.001676" ixy="-0.0000000635" ixz="0.0000000616" iyy="0.0004545" iyz="0.0002367" izz="0.001416"/>
    </inertial>
  </link>

  <link name="back_left_arm_link">
    <visual>
      <geometry>
        <mesh filename="package://stl/arm2.stl" scale="0.001 0.001 0.001"/>
      </geometry>
      <origin rpy="0 0 0" xyz="0 0 0"/> 
      <material name="white"/>
    </visual>
    <collision>
      <geometry>
        <box size="0.059 0.228758 0.08244"/>
      </geometry>
      <origin rpy="0 0 0" xyz="-0.052 0.0944 0.016025"/>
    </collision>
    <inertial>
      <mass value="0.500063"/>
			<origin rpy="0 0 0" xyz="-0.049769 0.079064 0.017355"/>
      <inertia ixx="0.001582" ixy="0.000088512" ixz="0.0000124983" iyy="0.0003877" iyz="0.0001209" izz="0.001477"/>
    </inertial>
  </link>

  <link name="back_left_hand_link">
    <visual>
      <geometry>
        <mesh filename="package://stl/foot1.stl" scale="0.001 0.001 0.001"/>
      </geometry>
      <origin rpy="0 0 0" xyz="0 0 0"/> 
      <material name="yellow"/>
    </visual>
    <collision>
      <geometry>
        <cylinder length="0.138" radius="0.0101"/>
      </geometry>
      <origin rpy="0 1.570796 0" xyz="0.100811 -0.036862 0"/>
    </collision>
    <collision>
      <geometry>
        <cylinder length="0.0202" radius="0.015"/>
      </geometry>
      <origin rpy="0 0 1.570796" xyz="0.171811 -0.036862 0"/>
    </collision>
    <inertial>
      <mass value="0.066814"/>
			<origin rpy="0 0 0" xyz="0.07927 -0.025916 0.001911"/>
      <inertia ixx="0.0000248576" ixy="0.0000574076" ixz="0.0000101035" iyy="0.0003695" iyz="-0.0000032878" izz="0.0003872"/>
    </inertial>
  </link>

  <joint name="base_to_back_left_shoulder" type="revolute">
    <parent link="base_link"/>
    <child link="back_left_shoulder_link"/>
    <axis xyz="0 1 0"/>
    <origin rpy="0 1.57079632679 1.57079632679" xyz="-0.2352235 0.0985 0"/>
    <limit effort="100.0" lower="-0.6051" upper="0.6051" velocity="100"/>
    <dynamics damping="0.0" friction="0"/>
  </joint>

  <joint name="back_left_shoulder_to_arm" type="revolute">
    <parent link="back_left_shoulder_link"/>
    <child link="back_left_arm_link"/>
    <axis xyz="0 0 -1"/>
    <origin rpy="0 0 -1.84649081579" xyz="0 0 0.0435"/>
    <limit effort="100.0" lower="-2.4337" upper="1.3135" velocity="100"/>
    <dynamics damping="0.0" friction="0"/>
  </joint>

  <joint name="back_left_arm_to_hand" type="revolute">
    <parent link="back_left_arm_link"/>
    <child link="back_left_hand_link"/>
    <axis xyz="0 0 1"/>
    <origin rpy="3.14159265359 0 1.655318169" xyz="-0.0519 0.183458 0"/>
    <limit effort="100.0" lower="-0.30696" upper="3.17664" velocity="100"/>
    <dynamics damping="0.0" friction="0"/>
  </joint>



  <link name="back_right_shoulder_link">
    <visual>
      <geometry>
        <mesh filename="package://stl/shoulder.stl" scale="0.001 0.001 0.001"/>
      </geometry>
      <origin rpy="0 0 0" xyz="0 0 0"/> 
      <material name="orange"/>
    </visual>
    <collision>
      <geometry>
        <box size="0.059 0.211013 0.118076"/>
      </geometry>
      <origin rpy="0 0 0" xyz="0 -0.080206 0.042257"/>
    </collision>
    <inertial>
      <mass value="0.505084"/>
			<origin rpy="0 0 0" xyz="-0.000225 -0.096893 0.058205"/>
      <inertia ixx="0.001676" ixy="-0.0000000635" ixz="0.0000000616" iyy="0.0004545" iyz="0.0002367" izz="0.001416"/>
    </inertial>
  </link>

  <link name="back_right_arm_link">
    <visual>
      <geometry>
        <mesh filename="package://stl/arm1.stl" scale="0.001 0.001 0.001"/>
      </geometry>
      <origin rpy="0 0 0" xyz="0 0 0"/> 
      <material name="white"/>
    </visual>
    <collision>
      <geometry>
        <box size="0.059 0.228758 0.08244"/>
      </geometry>
      <origin rpy="0 0 0" xyz="0.052 0.0944 0.016025"/>
    </collision>
    <inertial>
      <mass value="0.500063"/>
			<origin rpy="0 0 0" xyz="0.049769 0.079064 0.017355"/>
      <inertia ixx="0.001582" ixy="-0.0000885652" ixz="-0.0000123498" iyy="0.0003877" iyz="0.0001209" izz="0.001477"/>
    </inertial>
  </link>

  <link name="back_right_hand_link">
    <visual>
      <geometry>
        <mesh filename="package://stl/foot2.stl" scale="0.001 0.001 0.001"/>
      </geometry>
      <origin rpy="0 0 0" xyz="0 0 0"/> 
      <material name="yellow"/>
    </visual>
    <collision>
      <geometry>
        <cylinder length="0.138" radius="0.0101"/>
      </geometry>
      <origin rpy="0 1.570796 0" xyz="0.100811 -0.036862 0"/>
    </collision>
    <collision>
      <geometry>
        <cylinder length="0.0202" radius="0.015"/>
      </geometry>
      <origin rpy="0 0 1.570796" xyz="0.171811 -0.036862 0"/>
    </collision>
    <inertial>
      <mass value="0.066814"/>
			<origin rpy="0 0 0" xyz="0.07927 -0.025916 0.001911"/>
      <inertia ixx="0.0000248576" ixy="0.0000574076" ixz="0.0000101035" iyy="0.0003695" iyz="-0.0000032878" izz="0.0003872"/>
    </inertial>
  </link>

  <joint name="base_to_back_right_shoulder" type="revolute">
    <parent link="base_link"/>
    <child link="back_right_shoulder_link"/>
    <axis xyz="0 1 0"/>
    <origin rpy="0 -1.57079632679 1.57079632679" xyz="-0.2352235 -0.0985 0"/>
    <limit effort="100.0" lower="-0.6051" upper="0.6051" velocity="100"/>
    <dynamics damping="0.0" friction="0"/>
  </joint>

  <joint name="back_right_shoulder_to_arm" type="revolute">
    <parent link="back_right_shoulder_link"/>
    <child link="back_right_arm_link"/>
    <axis xyz="0 0 1"/>
    <origin rpy="0 0 1.84649081579" xyz="0 0 0.0435"/>
    <limit effort="100.0" lower="-2.4337" upper="1.3135" velocity="100"/>
    <dynamics damping="0.0" friction="0"/>
  </joint>

  <joint name="back_right_arm_to_hand" type="revolute">
    <parent link="back_right_arm_link"/>
    <child link="back_right_hand_link"/>
    <axis xyz="0 0 1"/>
    <origin rpy="0 0 1.48627448459" xyz="0.0519 0.183458 0"/>
    <limit effort="100.0" lower="-0.30696" upper="3.17664" velocity="100"/>
    <dynamics damping="0.0" friction="0"/>
  </joint>


</robot>
